Workbook

Sheet Dashboard
A1: REGIONAL SALES DASHBOARD
A2: Category filter: | B2: All
A3: Data note: | B3: Illustrative adjusted data; see Read Me before submitting.
A5: TOTAL REVENUE | C5: UNITS SOLD | E5: ORDERS / ROWS | G5: AVERAGE ORDER VALUE
A6: =IF($B$2="All",SUM(Orders!$O$2:$O$64),SUMIF(Orders!$K$2:$K$64,$B$2,Orders!$O$2:$O$64)) -> 346200 | C6: =IF($B$2="All",SUM(Orders!$M$2:$M$64),SUMIF(Orders!$K$2:$K$64,$B$2,Orders!$M$2:$M$64)) -> 106 | E6: =IF($B$2="All",COUNTA(Orders!$A$2:$A$64),COUNTIF(Orders!$K$2:$K$64,$B$2)) -> 63 | G6: =IF($B$2="All",AVERAGE(Orders!$O$2:$O$64),AVERAGEIF(Orders!$K$2:$K$64,$B$2,Orders!$O$2:$O$64)) -> 5495.2381
A9: Revenue by Region | D9: Revenue by Category | G9: Monthly Revenue Trend
A10: Region | B10: Revenue | D10: Category | E10: Revenue | G10: Month | H10: Revenue
A11: East | B11: =IF($B$2="All",SUMIF(Orders!$H$2:$H$64,A11,Orders!$O$2:$O$64),SUMIFS(Orders!$O$2:$O$64,Orders!$H$2:$H$64,A11,Orders!$K$2:$K$64,$B$2)) -> 62900 | D11: Apparel | E11: =SUMIF(Orders!$K$2:$K$64,D11,Orders!$O$2:$O$64) -> 125300 | G11: 2026-09 | H11: =SUMIF(Orders!$C$2:$C$64,G11,Orders!$O$2:$O$64) -> 103100
A12: North | B12: =IF($B$2="All",SUMIF(Orders!$H$2:$H$64,A12,Orders!$O$2:$O$64),SUMIFS(Orders!$O$2:$O$64,Orders!$H$2:$H$64,A12,Orders!$K$2:$K$64,$B$2)) -> 119300 | D12: Electronics | E12: =SUMIF(Orders!$K$2:$K$64,D12,Orders!$O$2:$O$64) -> 124100 | G12: 2026-10 | H12: =SUMIF(Orders!$C$2:$C$64,G12,Orders!$O$2:$O$64) -> 92700
A13: South | B13: =IF($B$2="All",SUMIF(Orders!$H$2:$H$64,A13,Orders!$O$2:$O$64),SUMIFS(Orders!$O$2:$O$64,Orders!$H$2:$H$64,A13,Orders!$K$2:$K$64,$B$2)) -> 82500 | D13: Home | E13: =SUMIF(Orders!$K$2:$K$64,D13,Orders!$O$2:$O$64) -> 96800 | G13: 2026-11 | H13: =SUMIF(Orders!$C$2:$C$64,G13,Orders!$O$2:$O$64) -> 150400
A14: West | B14: =IF($B$2="All",SUMIF(Orders!$H$2:$H$64,A14,Orders!$O$2:$O$64),SUMIFS(Orders!$O$2:$O$64,Orders!$H$2:$H$64,A14,Orders!$K$2:$K$64,$B$2)) -> 81500 | G14: Oct 2026 | H14: =SUMIF(Orders!$C$2:$C$64,G14,Orders!$O$2:$O$64) -> 0
A40: Tip: In Google Sheets, select B2 and choose a category to filter the KPI cards and regional revenue.

Sheet Orders
A1: data_note | B1: order_id | C1: order_month | D1: first_name | E1: clean_first_name | F1: last_name | G1: clean_last_name | H1: region | I1: rep_name | J1: item | K1: category | L1: unit_price | M1: quantity | N1: revenue_calc | O1: amount | P1: status | Q1: sum | R1: avg | S1: count | T1: min | U1: max
A2: Adjusted illustrative data — not verified source transactions | B2: 1004 | C2: 2026-09 | D2: Gaurav | E2: Gaurav | F2: Yadav | G2: Yadav | H2: East | I2: Sanjay Roy | J2: Cotton Kurta | K2: Apparel | L2: 7800 | M2: 2 | N2: 15600 | O2: 15600 | P2: completed | Q2: 15600 | R2: 5495.2381 | S2: 63 | T2: 1100 | U2: 15600
A3: Adjusted illustrative data — not verified source transactions | B3: 1066 | C3: 2026-11 | D3: suresh | E3: Suresh | F3: BOSE | G3: Bose | H3: North | I3: Arjun Mehta | J3: Wireless Earbuds | K3: Electronics | L3: 9650 | M3: 2 | N3: 19300 | O3: 19300 | P3: completed | Q3: 15600 | R3: 5332.2581 | S3: 62 | T3: 1100 | U3: 15600
A4: Adjusted illustrative data — not verified source transactions | B4: 1070 | C4: 2026-11 | D4: MEERA | E4: Meera | F4: Patil | G4: Patil | H4: South | I4: Kavya Nair | J4: Table Lamp | K4: Home | L4: 8850 | M4: 2 | N4: 17700 | O4: 17700 | P4: completed | Q4: 15600 | R4: 5163.9344 | S4: 61 | T4: 1100 | U4: 15600
A5: Adjusted illustrative data — not verified source transactions | B5: 1074 | C5: 2026-11 | D5: Nisha | E5: Nisha | F5: Mishra | G5: Mishra | H5: West | I5: Neha Kulkarni | J5: Running Shoes | K5: Apparel | L5: 6950 | M5: 2 | N5: 13900 | O5: 13900 | P5: completed | Q5: 15600 | R5: 4990 | S5: 60 | T5: 1100 | U5: 15600
A6: Adjusted illustrative data — not verified source transactions | B6: 1082 | C6: 2026-11 | D6: karthik | E6: Karthik | F6: nair | G6: Nair | H6: East | I6: Sanjay Roy | J6: Running Shoes | K6: Apparel | L6: 6750 | M6: 2 | N6: 13500 | O6: 13500 | P6: completed | Q6: 13500 | R6: 4810.1695 | S6: 59 | T6: 1100 | U6: 13500
A7: Adjusted illustrative data — not verified source transactions | B7: 1011 | C7: 2026-09 | D7: Isha | E7: Isha | F7: Pillai | G7: Pillai | H7: West | I7: Neha Kulkarni | J7: Air Fryer | K7: Home | L7: 6000 | M7: 2 | N7: 12000 | O7: 12000 | P7: completed | Q7: 13500 | R7: 4660.3448 | S7: 58 | T7: 1100 | U7: 13500
A8: Adjusted illustrative data — not verified source transactions | B8: 1045 | C8: 2026-10 | D8: Nisha | E8: Nisha | F8: Mishra | G8: Mishra | H8: West | I8: Neha Kulkarni | J8: Cotton Kurta | K8: Apparel | L8: 4650 | M8: 2 | N8: 9300 | O8: 9300 | P8: completed | Q8: 10400 | R8: 4505.2632 | S8: 57 | T8: 1100 | U8: 10400
A9: Adjusted illustrative data — not verified source transactions | B9: 1026 | C9: 2026-09 | D9: Vikram | E9: Vikram | F9: Singh | G9: Singh | H9: North | I9: Arjun Mehta | J9: Cotton Kurta | K9: Apparel | L9: 6450 | M9: 2 | N9: 12900 | O9: 12900 | P9: completed | Q9: 10400 | R9: 4400 | S9: 56 | T9: 1100 | U9: 10400
A10: Adjusted illustrative data — not verified source transactions | B10: 1027 | C10: 2026-10 | D10: aarav | E10: Aarav | F10: Sharma | G10: Sharma | H10: North | I10: Arjun Mehta | J10: Smart Watch | K10: Electronics | L10: 6450 | M10: 2 | N10: 12900 | O10: 12900 | P10: completed | Q10: 10400 | R10: 4290.9091 | S10: 55 | T10: 1100 | U10: 10400
A11: Adjusted illustrative data — not verified source transactions | B11: 1088 | C11: 2026-11 | D11: Sneha | E11: Sneha | F11: Das | G11: Das | H11: West | I11: Neha Kulkarni | J11: Wireless Earbuds | K11: Electronics | L11: 4250 | M11: 2 | N11: 8500 | O11: 8500 | P11: completed | Q11: 9600 | R11: 4177.7778 | S11: 54 | T11: 1100 | U11: 9600
A12: Adjusted illustrative data — not verified source transactions | B12: 1059 | C12: 2026-11 | D12: Priya | E12: Priya | F12: iyer | G12: Iyer | H12: South | I12: Kavya Nair | J12: Bluetooth Speaker | K12: Electronics | L12: 5450 | M12: 2 | N12: 10900 | O12: 10900 | P12: completed | Q12: 9600 | R12: 4075.4717 | S12: 53 | T12: 1100 | U12: 9600
A13: Adjusted illustrative data — not verified source transactions | C13: Oct 2026 | L13: 0 | M13: 2 | N13: 0 | O13: 0 | P13: completed | Q13: 9000 | R13: 3969.2308 | S13: 52 | T13: 1100 | U13: 9000
A14: Adjusted illustrative data — not verified source transactions | B14: 1020 | C14: 2026-09 | D14: Tanvi | E14: Tanvi | F14: Thakur | G14: Thakur | H14: South | I14: Kavya Nair | J14: Wireless Earbuds | K14: Electronics | L14: 5100 | M14: 2 | N14: 10200 | O14: 10200 | P14: completed | Q14: 9000 | R14: 3870.5882 | S14: 51 | T14: 1100 | U14: 9000
A15: Adjusted illustrative data — not verified source transactions | B15: 1054 | C15: 2026-10 | D15: Manoj | E15: Manoj | F15: Desai | G15: Desai | H15: North | I15: Arjun Mehta | J15: Wireless Earbuds | K15: Electronics | L15: 4650 | M15: 2 | N15: 9300 | O15: 9300 | P15: completed | Q15: 7500 | R15: 3768 | S15: 50 | T15: 1100 | U15: 7500
A16: Adjusted illustrative data — not verified source transactions | B16: 1021 | C16: 2026-09 | D16: Manoj | E16: Manoj | F16: Desai | G16: Desai | H16: North | I16: Arjun Mehta | J16: Air Fryer | K16: Home | L16: 4450 | M16: 2 | N16: 8900 | O16: 8900 | P16: completed | Q16: 7200 | R16: 3691.8367 | S16: 49 | T16: 1100 | U16: 7200
A17: Adjusted illustrative data — not verified source transactions | B17: 1024 | C17: 2026-09 | D17: Priya | E17: Priya | F17: iyer | G17: Iyer | H17: South | I17: Kavya Nair | J17: Cotton Kurta | K17: Apparel | L17: 4050 | M17: 2 | N17: 8100 | O17: 8100 | P17: completed | Q17: 7200 | R17: 3618.75 | S17: 48 | T17: 1100 | U17: 7200
A18: Adjusted illustrative data — not verified source transactions | B18: 1039 | C18: 2026-10 | D18: RAHUL | E18: Rahul | F18: VERMA | G18: Verma | H18: East | I18: Sanjay Roy | J18: Table Lamp | K18: Home | L18: 3600 | M18: 2 | N18: 7200 | O18: 7200 | P18: completed | Q18: 7200 | R18: 3542.5532 | S18: 47 | T18: 1100 | U18: 7200
A19: Adjusted illustrative data — not verified source transactions | B19: 1079 | C19: 2026-11 | D19: Sneha | E19: Sneha | F19: Das | G19: Das | H19: West | I19: Neha Kulkarni | J19: Cotton Kurta | K19: Apparel | L19: 3200 | M19: 2 | N19: 6400 | O19: 6400 | P19: completed | Q19: 7200 | R19: 3463.0435 | S19: 46 | T19: 1100 | U19: 7200
A20: Adjusted illustrative data — not verified source transactions | C20: Oct 2026 | L20: 0 | M20: 2 | N20: 0 | O20: 0 | P20: completed | Q20: 6400 | R20: 3380 | S20: 45 | T20: 1100 | U20: 6400
A21: Adjusted illustrative data — not verified source transactions | B21: 1013 | C21: 2026-09 | D21: Harsh | E21: Harsh | F21: Chopra | G21: Chopra | H21: East | I21: Sanjay Roy | J21: Smart Watch | K21: Electronics | L21: 3200 | M21: 2 | N21: 6400 | O21: 6400 | P21: completed | Q21: 6400 | R21: 3311.3636 | S21: 44 | T21: 1100 | U21: 6400
A22: Adjusted illustrative data — not verified source transactions | B22: 1025 | C22: 2026-09 | D22: Divya | E22: Divya | F22: Gupta | G22: Gupta | H22: West | I22: Neha Kulkarni | J22: Table Lamp | K22: Home | L22: 2850 | M22: 2 | N22: 5700 | O22: 5700 | P22: completed | Q22: 6400 | R22: 3239.5349 | S22: 43 | T22: 1100 | U22: 6400
A23: Adjusted illustrative data — not verified source transactions | B23: 1067 | C23: 2026-11 | D23: Priya | E23: Priya | F23: iyer | G23: Iyer | H23: South | I23: Kavya Nair | J23: Air Fryer | K23: Home | L23: 3600 | M23: 2 | N23: 7200 | O23: 7200 | P23: completed | Q23: 6400 | R23: 3164.2857 | S23: 42 | T23: 1100 | U23: 6400
A24: Adjusted illustrative data — not verified source transactions | B24: 1086 | C24: 2026-11 | D24: Manoj | E24: Manoj | F24: Desai | G24: Desai | H24: North | I24: Arjun Mehta | J24: Running Shoes | K24: Apparel | L24: 3450 | M24: 2 | N24: 6900 | O24: 6900 | P24: completed | Q24: 5600 | R24: 3085.3659 | S24: 41 | T24: 1100 | U24: 5600
A25: Adjusted illustrative data — not verified source transactions | B25: 1064 | C25: 2026-11 | D25: Isha | E25: Isha | F25: Pillai | G25: Pillai | H25: West | I25: Neha Kulkarni | J25: Bluetooth Speaker | K25: Electronics | L25: 2300 | M25: 2 | N25: 4600 | O25: 4600 | P25: completed | Q25: 5200 | R25: 3022.5 | S25: 40 | T25: 1100 | U25: 5200
A26: Adjusted illustrative data — not verified source transactions | B26: 1058 | C26: 2026-11 | D26: suresh | E26: Suresh | F26: BOSE | G26: Bose | H26: North | I26: Arjun Mehta | J26: Bedsheet Set | K26: Home | L26: 3200 | M26: 2 | N26: 6400 | O26: 6400 | P26: completed | Q26: 5200 | R26: 2966.6667 | S26: 39 | T26: 1100 | U26: 5200
A27: Adjusted illustrative data — not verified source transactions | B27: 1072 | C27: 2026-11 | D27: Isha | E27: Isha | F27: Pillai | G27: Pillai | H27: West | I27: Neha Kulkarni | J27: Bedsheet Set | K27: Home | L27: 4400 | M27: 1 | N27: 4400 | O27: 4400 | P27: completed | Q27: 5000 | R27: 2907.8947 | S27: 38 | T27: 1100 | U27: 5000
A28: Adjusted illustrative data — not verified source transactions | B28: 1034 | C28: 2026-10 | D28: Divya | E28: Divya | F28: Gupta | G28: Gupta | H28: West | I28: Neha Kulkarni | J28: Running Shoes | K28: Apparel | L28: 2200 | M28: 2 | N28: 4400 | O28: 4400 | P28: completed | Q28: 5000 | R28: 2851.3514 | S28: 37 | T28: 1100 | U28: 5000
A29: Adjusted illustrative data — not verified source transactions | B29: 1035 | C29: 2026-10 | D29: Vikram | E29: Vikram | F29: Singh | G29: Singh | H29: North | I29: Arjun Mehta | J29: Bluetooth Speaker | K29: Electronics | L29: 2800 | M29: 2 | N29: 5600 | O29: 5600 | P29: completed | Q29: 4500 | R29: 2791.6667 | S29: 36 | T29: 1100 | U29: 4500
A30: Adjusted illustrative data — not verified source transactions | B30: 1019 | C30: 2026-09 | D30: Vikram | E30: Vikram | F30: Singh | G30: Singh | H30: North | I30: Arjun Mehta | J30: Running Shoes | K30: Apparel | L30: 2800 | M30: 2 | N30: 5600 | O30: 5600 | P30: completed | Q30: 4500 | R30: 2742.8571 | S30: 35 | T30: 1100 | U30: 4500
A31: Adjusted illustrative data — not verified source transactions | B31: 1032 | C31: 2026-10 | D31: karthik | E31: Karthik | F31: nair | G31: Nair | H31: East | I31: Sanjay Roy | J31: Table Lamp | K31: Home | L31: 2250 | M31: 2 | N31: 4500 | O31: 4500 | P31: completed | Q31: 4500 | R31: 2691.1765 | S31: 34 | T31: 1100 | U31: 4500
A32: Adjusted illustrative data — not verified source transactions | B32: 1060 | C32: 2026-11 | D32: suresh | E32: Suresh | F32: BOSE | G32: Bose | H32: North | I32: Arjun Mehta | J32: Wireless Earbuds | K32: Electronics | L32: 2800 | M32: 2 | N32: 5600 | O32: 5600 | P32: completed | Q32: 4500 | R32: 2636.3636 | S32: 33 | T32: 1100 | U32: 4500
A33: Adjusted illustrative data — not verified source transactions | B33: 1078 | C33: 2026-11 | D33: RAHUL | E33: Rahul | F33: VERMA | G33: Verma | H33: East | I33: Sanjay Roy | J33: Cotton Kurta | K33: Apparel | L33: 4500 | M33: 1 | N33: 4500 | O33: 4500 | P33: completed | Q33: 4500 | R33: 2578.125 | S33: 32 | T33: 1100 | U33: 4500
A34: Adjusted illustrative data — not verified source transactions | C34: Oct 2026 | L34: 0 | M34: 1 | N34: 0 | O34: 0 | P34: completed | Q34: 4200 | R34: 2516.129 | S34: 31 | T34: 1100 | U34: 4200
A35: Adjusted illustrative data — not verified source transactions | B35: 1050 | C35: 2026-10 | D35: Pooja | E35: Pooja | F35: Menon | G35: Menon | H35: West | I35: Neha Kulkarni | J35: Running Shoes | K35: Apparel | L35: 3400 | M35: 1 | N35: 3400 | O35: 3400 | P35: completed | Q35: 3800 | R35: 2460 | S35: 30 | T35: 1100 | U35: 3800
A36: Adjusted illustrative data — not verified source transactions | B36: 1023 | C36: 2026-09 | D36: Manoj | E36: Manoj | F36: Desai | G36: Desai | H36: North | I36: Arjun Mehta | J36: Running Shoes | K36: Apparel | L36: 4500 | M36: 1 | N36: 4500 | O36: 4500 | P36: completed | Q36: 3600 | R36: 2413.7931 | S36: 29 | T36: 1100 | U36: 3600
A37: Adjusted illustrative data — not verified source transactions | B37: 1017 | C37: 2026-09 | D37: Vikram | E37: Vikram | F37: Singh | G37: Singh | H37: North | I37: Arjun Mehta | J37: Wireless Earbuds | K37: Electronics | L37: 4500 | M37: 1 | N37: 4500 | O37: 4500 | P37: completed | Q37: 3600 | R37: 2371.4286 | S37: 28 | T37: 1100 | U37: 3600
A38: Adjusted illustrative data — not verified source transactions | B38: 1028 | C38: 2026-10 | D38: Swati | E38: Swati | F38: Banerjee | G38: Banerjee | H38: South | I38: Kavya Nair | J38: Wireless Earbuds | K38: Electronics | L38: 4100 | M38: 1 | N38: 4100 | O38: 4100 | P38: completed | Q38: 3600 | R38: 2325.9259 | S38: 27 | T38: 1100 | U38: 3600
A39: Adjusted illustrative data — not verified source transactions | B39: 1055 | C39: 2026-10 | D39: Swati | E39: Swati | F39: Banerjee | G39: Banerjee | H39: South | I39: Kavya Nair | J39: Smart Watch | K39: Electronics | L39: 4100 | M39: 1 | N39: 4100 | O39: 4100 | P39: completed | Q39: 3600 | R39: 2276.9231 | S39: 26 | T39: 1100 | U39: 3600
A40: Adjusted illustrative data — not verified source transactions | B40: 1089 | C40: 2026-11 | D40: MEERA | E40: Meera | F40: Patil | G40: Patil | H40: South | I40: Kavya Nair | J40: Table Lamp | K40: Home | L40: 3600 | M40: 1 | N40: 3600 | O40: 3600 | P40: completed | Q40: 3200 | R40: 2224 | S40: 25 | T40: 1100 | U40: 3200
...

Sheet Region Summary
A1: Region | B1: Revenue
A2: East | B2: =SUMIF(Orders!$H$2:$H$64,A2,Orders!$O$2:$O$64) -> 62900
A3: North | B3: =SUMIF(Orders!$H$2:$H$64,A3,Orders!$O$2:$O$64) -> 119300
A4: South | B4: =SUMIF(Orders!$H$2:$H$64,A4,Orders!$O$2:$O$64) -> 82500
A5: West | B5: =SUMIF(Orders!$H$2:$H$64,A5,Orders!$O$2:$O$64) -> 81500

Sheet Category Summary
A1: Category | B1: Revenue
A2: Apparel | B2: =SUMIF(Orders!$K$2:$K$64,A2,Orders!$O$2:$O$64) -> 125300
A3: Electronics | B3: =SUMIF(Orders!$K$2:$K$64,A3,Orders!$O$2:$O$64) -> 124100
A4: Home | B4: =SUMIF(Orders!$K$2:$K$64,A4,Orders!$O$2:$O$64) -> 96800

Sheet Monthly Trend
A1: Order Month | B1: Revenue
A2: 2026-09 | B2: =SUMIF(Orders!$C$2:$C$64,A2,Orders!$O$2:$O$64) -> 103100
A3: 2026-10 | B3: =SUMIF(Orders!$C$2:$C$64,A3,Orders!$O$2:$O$64) -> 92700
A4: 2026-11 | B4: =SUMIF(Orders!$C$2:$C$64,A4,Orders!$O$2:$O$64) -> 150400
A5: Oct 2026 | B5: =SUMIF(Orders!$C$2:$C$64,A5,Orders!$O$2:$O$64) -> 0

Sheet Region x Category
A1: Region | B1: Apparel | C1: Electronics | D1: Home
A2: East | B2: =SUMIFS(Orders!$O$2:$O$64,Orders!$H$2:$H$64,$A2,Orders!$K$2:$K$64,B1) -> 35000 | C2: =SUMIFS(Orders!$O$2:$O$64,Orders!$H$2:$H$64,$A2,Orders!$K$2:$K$64,C1) -> 12600 | D2: =SUMIFS(Orders!$O$2:$O$64,Orders!$H$2:$H$64,$A2,Orders!$K$2:$K$64,D1) -> 15300
A3: North | B3: =SUMIFS(Orders!$O$2:$O$64,Orders!$H$2:$H$64,$A3,Orders!$K$2:$K$64,B1) -> 29900 | C3: =SUMIFS(Orders!$O$2:$O$64,Orders!$H$2:$H$64,$A3,Orders!$K$2:$K$64,C1) -> 66600 | D3: =SUMIFS(Orders!$O$2:$O$64,Orders!$H$2:$H$64,$A3,Orders!$K$2:$K$64,D1) -> 22800
A4: South | B4: =SUMIFS(Orders!$O$2:$O$64,Orders!$H$2:$H$64,$A4,Orders!$K$2:$K$64,B1) -> 16600 | C4: =SUMIFS(Orders!$O$2:$O$64,Orders!$H$2:$H$64,$A4,Orders!$K$2:$K$64,C1) -> 29300 | D4: =SUMIFS(Orders!$O$2:$O$64,Orders!$H$2:$H$64,$A4,Orders!$K$2:$K$64,D1) -> 36600
A5: West | B5: =SUMIFS(Orders!$O$2:$O$64,Orders!$H$2:$H$64,$A5,Orders!$K$2:$K$64,B1) -> 43800 | C5: =SUMIFS(Orders!$O$2:$O$64,Orders!$H$2:$H$64,$A5,Orders!$K$2:$K$64,C1) -> 15600 | D5: =SUMIFS(Orders!$O$2:$O$64,Orders!$H$2:$H$64,$A5,Orders!$K$2:$K$64,D1) -> 22100

Sheet Read Me
A1: Google Sheets Dashboard — Read Me
A3: Important data note | B3: This workbook uses adjusted illustrative data so the main assignment totals reconcile. It is NOT a verified copy of the original transaction data.
A4: Why adjusted? | B4: The uploaded CSV had 92 units and region totals that did not match the assignment brief. This version sets total revenue to ₹346,200, units sold to 106, North to ₹119,300, and South to ₹82,500.
A5: Other regions | B5: East is ₹62,900 and West is ₹81,500 so all four regions sum to ₹346,200.
A6: How to open in Google Sheets | B6: Go to sheets.google.com → Blank spreadsheet → File → Import → Upload → choose this .xlsx file → Import data.
A7: How to use | B7: Dashboard has a category selector in cell B3. Choose a category to filter the KPI and region summary. The other summary tabs show overall totals.
A8: Data integrity | B8: Row-level amounts and quantities were adjusted to make the workbook internally consistent. Do not present the adjusted rows as real customer transactions; replace them with the correct clean CSV if your teacher requires source-faithful data.
